Workbook

Sheet СР (материалы ТН)
E1: Приложение №1
E2: к договору №__.__-Д/В__ от __.__.2026 г.
A4: РАСЧЕТ СТОИМОСТИ РАБОТ
A6: Наименование работ | B6: Ед. изм. | C6: Кол-во | D6: Цена за ед. без НДС | E6: Сумма без НДС
A7: Демонтажные работы в осях 36-47/П-Э
A8: Демонтаж гидроизоляционного слоя | B8: м2 | C8: =(11*48*2)+(2*18*2) -> 1128 | D8: 80 | E8: =C8*D8 -> 90240
A9: Демонтаж теплоизоляционного слоя | B9: м2 | C9: =(11.2*48*2)+(1.2*18*2) -> 1118.4 | D9: 100 | E9: =C9*D9 -> 111840
A10: Демонтаж профилированного настила | B10: м2 | C10: =(9*48*2)+(0.86*18*2) -> 894.96 | D10: 180 | E10: =C10*D10 -> 161092.8
A11: Итого за работы: | E11: =SUM(E8:E10) -> 363172.8
A12: ИТОГО по Разделу: | E12: =E11 -> 363172.8
A13: Монтаж профилированного настила
A14: Работы:
A15: Монтаж профилированного настила Н-114 | B15: м2 | C15: =C10 -> 894.96 | D15: 140,00 ₽ | E15: =D15*C15 -> 125294.4
A16: Итого за работы: | E16: =E15 -> 125294.4
A17: ИТОГО по Разделу: | E17: =E16 -> 125294.4
A18: Устройство L-образного профиля в местах парапета и профилей усиления в ендове и на коньках, устройство профиля усиления деф. швов
A19: Работы:
A20: Устройство L-образного профиля и профилей усиления | B20: м/п | C20: =18+9+9 -> 36 | D20: 20,00 ₽ | E20: =D20*C20 -> 720
A21: Устройство профилей усиления (коньковые усиления, усиления ендов) | B21: м/п | C21: 0 | D21: 10,00 ₽ | E21: =D21*C21 -> 0
A22: Устройство профилей усиления деф. шва | B22: м/п | C22: 0 | D22: 10,00 ₽ | E22: =D22*C22 -> 0
A23: Итого за работы: | E23: =SUM(E20:E22) -> 720
A24: Материалы:
A25: L-образный профиль | B25: мп | C25: =C20 -> 36 | D25: 1300 | E25: =C25*D25 -> 46800
A26: Профиль усиления (коньковые усиления, усиления ендов) | B26: мп | C26: =C21 -> 0 | D26: 1300 | E26: =C26*D26 -> 0
A27: Профиль усиления деф. шва | B27: мп | C27: =C22 -> 0 | D27: 1300 | E27: =C27*D27 -> 0
A28: Саморез кровельный 4.8х29 сверлоконечный шайба EPDM | B28: шт | C28: =(C25+C26+C27)*2*5 -> 360 | D28: 5 | E28: =C28*D28 -> 1800
A29: Итого за материалы: | E29: =SUM(E25:E28) -> 48600
A30: ИТОГО по Разделу: | E30: =E23+E29 -> 49320
A31: Устройство шины молниезащиты/ заземления
A32: Работы:
A33: Монтаж шины молниезащиты (механическое крепление) | B33: м/п | C33: 0 | D33: 200,00 ₽ | E33: =C33*D33 -> 0
A34: Итого за работы: | E34: =E33 -> 0
A35: ИТОГО по Разделу: | E35: =E34 -> 0
A36: Устройство усиления мест воронок внутреннего водоотведения
A37: Работы:
A38: Устройство усиления мест воронок внутреннего водоотведения из оц. стали толщиной 0,5 мм размером 0,6*0,6 м | B38: шт | C38: 0 | D38: 100,00 ₽ | E38: =D38*C38 -> 0
A39: Итого за работы: | E39: =E38 -> 0
A40: Материалы:
A41: Оцинкованный лист, толщ. 0,7 мм, 600*600 мм | B41: шт | C41: =C38 -> 0 | D41: 1300 | E41: =D41*C41 -> 0
A42: Саморез кровельный 4.8х29 сверлоконечный шайба EPDM | B42: шт | C42: =C38*4 -> 0 | D42: =D28 -> 5 | E42: =D42*C42 -> 0
...

Sheet СР (материалы Фахман)
E1: Приложение №1
E2: к договору №__.__-Д/В__ от __.__.2026 г.
A4: РАСЧЕТ СТОИМОСТИ РАБОТ
A6: Наименование работ | B6: Ед. изм. | C6: Кол-во | D6: Цена за ед. без НДС | E6: Сумма без НДС
A7: Демонтажные работы в осях 36-47/П-Э
A8: Демонтаж гидроизоляционного слоя | B8: м2 | C8: ='СР (материалы ТН)'!C8 -> 1128 | D8: ='СР (материалы ТН)'!D8 -> 80 | E8: =C8*D8 -> 90240
A9: Демонтаж теплоизоляционного слоя | B9: м2 | C9: ='СР (материалы ТН)'!C9 -> 1118.4 | D9: ='СР (материалы ТН)'!D9 -> 100 | E9: =C9*D9 -> 111840
A10: Демонтаж профилированного настила | B10: м2 | C10: ='СР (материалы ТН)'!C10 -> 894.96 | D10: ='СР (материалы ТН)'!D10 -> 180 | E10: =C10*D10 -> 161092.8
A11: Итого за работы: | E11: =SUM(E8:E10) -> 363172.8
A12: ИТОГО по Разделу: | E12: =E11 -> 363172.8
A13: Монтаж профилированного настила
A14: Работы:
A15: Монтаж профилированного настила Н-114 | B15: м2 | C15: ='СР (материалы ТН)'!C15 -> 894.96 | D15: ='СР (материалы ТН)'!D15 -> 140,00 ₽ | E15: =D15*C15 -> 125294.4
A16: Итого за работы: | E16: =E15 -> 125294.4
A17: ИТОГО по Разделу: | E17: =E16 -> 125294.4
A18: Устройство L-образного профиля в местах парапета и профилей усиления в ендове и на коньках, устройство профиля усиления деф. швов
A19: Работы:
A20: Устройство L-образного профиля и профилей усиления | B20: м/п | C20: ='СР (материалы ТН)'!C20 -> 36 | D20: ='СР (материалы ТН)'!D20 -> 20,00 ₽ | E20: =D20*C20 -> 720
A21: Устройство профилей усиления (коньковые усиления, усиления ендов) | B21: м/п | C21: ='СР (материалы ТН)'!C21 -> 0 | D21: ='СР (материалы ТН)'!D21 -> 10,00 ₽ | E21: =D21*C21 -> 0
A22: Устройство профилей усиления деф. шва | B22: м/п | C22: ='СР (материалы ТН)'!C22 -> 0 | D22: ='СР (материалы ТН)'!D22 -> 10,00 ₽ | E22: =D22*C22 -> 0
A23: Итого за работы: | E23: =SUM(E20:E22) -> 720
A24: Материалы:
A25: L-образный профиль | B25: мп | C25: ='СР (материалы ТН)'!C25 -> 36 | D25: 1284 | E25: =C25*D25 -> 46224
A26: Профиль усиления (коньковые усиления, усиления ендов) | B26: мп | C26: ='СР (материалы ТН)'!C26 -> 0 | D26: ='СР (материалы ТН)'!D26 -> 1300 | E26: =C26*D26 -> 0
A27: Профиль усиления деф. шва | B27: мп | C27: ='СР (материалы ТН)'!C27 -> 0 | D27: ='СР (материалы ТН)'!D27 -> 1300 | E27: =C27*D27 -> 0
A28: Саморез кровельный 4.8х29 сверлоконечный шайба EPDM | B28: шт | C28: ='СР (материалы ТН)'!C28 -> 360 | D28: 2.35 | E28: =C28*D28 -> 846
A29: Итого за материалы: | E29: =SUM(E25:E28) -> 47070
A30: ИТОГО по Разделу: | E30: =E23+E29 -> 47790
A31: Устройство шины молниезащиты/ заземления
A32: Работы:
A33: Монтаж шины молниезащиты (механическое крепление) | B33: м/п | C33: ='СР (материалы ТН)'!C33 -> 0 | D33: ='СР (материалы ТН)'!D33 -> 200,00 ₽ | E33: =C33*D33 -> 0
A34: Итого за работы: | E34: =E33 -> 0
A35: ИТОГО по Разделу: | E35: =E34 -> 0
A36: Устройство усиления мест воронок внутреннего водоотведения
A37: Работы:
A38: Устройство усиления мест воронок внутреннего водоотведения из оц. стали толщиной 0,5 мм размером 0,6*0,6 м | B38: шт | C38: ='СР (материалы ТН)'!C38 -> 0 | D38: ='СР (материалы ТН)'!D38 -> 100,00 ₽ | E38: =D38*C38 -> 0
A39: Итого за работы: | E39: =E38 -> 0
A40: Материалы:
A41: Оцинкованный лист, толщ. 0,7 мм, 600*600 мм | B41: шт | C41: ='СР (материалы ТН)'!C41 -> 0 | D41: ='СР (материалы ТН)'!D41 -> 1300 | E41: =D41*C41 -> 0
A42: Саморез кровельный 4.8х29 сверлоконечный шайба EPDM | B42: шт | C42: ='СР (материалы ТН)'!C42 -> 0 | D42: =D28 -> 2.35 | E42: =D42*C42 -> 0
...

Sheet Ведомость материалов
A1: Наименование работ. | B1: Ед.изм. | C1: Кол-во | D1: Цена за ед. (с НДС-22%) ТН | E1: Сумма ТН (с НДС-22%) | F1: Цена за ед. (с НДС-22%) Фахман | G1: Сумма Фахман (с НДС-22%)
A2: Мин. плита Технолайт Экстра 1200х600х100мм | B2: м3 | C2: ='СР (материалы ТН)'!C50 -> 1.188 | D2: 3700 | E2: =C2*D2 -> 4395.6 | F2: =D2 -> 3700 | G2: =C2*F2 -> 4395.6
A3: L-образный профиль | B3: м/п | C3: ='СР (материалы ТН)'!C25 -> 36 | D3: 1300 | E3: =C3*D3 -> 46800 | F3: 1284 | G3: =C3*F3 -> 46224
A4: Саморез кровельный 4.8х29 сверлоконечный шайба EPDM | B4: шт | C4: ='СР (материалы ТН)'!C28+'СР (материалы ТН)'!C42 -> 360 | D4: 5 | E4: =C4*D4 -> 1800 | F4: 2.35 | G4: =C4*F4 -> 846
A5: Пароизоляционная пленка ТехноНИКОЛЬ | B5: м2 | C5: ='СР (материалы ТН)'!C58 -> 1029.204 | D5: 19.9 | E5: =C5*D5 -> 20481.16 | F5: 26.44 | G5: =C5*F5 -> 27212.154
A6: Двусторонний скотч | B6: шт | C6: ='СР (материалы ТН)'!C59 -> 12 | D6: 308 | E6: =C6*D6 -> 3696 | F6: 190.36 | G6: =C6*F6 -> 2284.32
A7: Теплоизоляционный материал ТЕХНОРУФ В ЭКСТРА 50 мм | B7: м3 | C7: ='СР (материалы ТН)'!C72+'СР (материалы ТН)'!C113 -> 57.8244 | D7: 16112 | E7: =C7*D7 -> 931666.73 | F7: =D7 -> 16112 | G7: =C7*F7 -> 931666.73
A8: Саморез сверлоконечный ТехноНИКОЛЬ 4,8х80 мм | B8: шт | C8: ='СР (материалы ТН)'!C74+'СР (материалы ТН)'!C84 -> 11232 | D8: 13 | E8: =C8*D8 -> 146016 | F8: 6.53 | G8: =C8*F8 -> 73344.96
A9: ПВХ Logicroof V-RP 1,2 мм мембрана серая 2,10x25 м | B9: м2 | C9: ='СР (материалы ТН)'!C82+'СР (материалы ТН)'!C93+'СР (материалы ТН)'!C114 -> 1388.016 | D9: 931 | E9: =C9*D9 -> 1292242.9 | F9: =D9 -> 931 | G9: =C9*F9 -> 1292242.9
A10: ПВХ Logicroof V-SR 1,5 мм мембрана серая 2 шт. 1x10 м | B10: рул. | C10: ='СР (материалы ТН)'!C94+'СР (материалы ТН)'!C115 -> 16.6 | D10: 1350 | E10: =C10*D10 -> 22410 | F10: =D10 -> 1350 | G10: =C10*F10 -> 22410
A11: Прижимная кровельная планка алюминиевая 30*2000мм | B11: м/п | C11: ='СР (материалы ТН)'!C102 -> 36 | D11: 116 | E11: =C11*D11 -> 4176 | F11: 75.66 | G11: =C11*F11 -> 2723.76
A12: Краевая кровельная планка алюминиевая 30*2000мм | B12: м/п | C12: ='СР (материалы ТН)'!C103+'СР (материалы ТН)'!C117 -> 45 | D12: 150 | E12: =C12*D12 -> 6750 | F12: 83.8 | G12: =C12*F12 -> 3771
A13: Крепеж кровельный ТехноНИКОЛЬ (саморез 5,5*35) | B13: шт | C13: ='СР (материалы ТН)'!C104+'СР (материалы ТН)'!C118 -> 480 | D13: 8 | E13: =C13*D13 -> 3840 | F13: 5.07 | G13: =C13*F13 -> 2433.6
A14: Очиститель для ПВХ мембраны, 3 л. | B14: шт | C14: ='СР (материалы ТН)'!C85 -> 5 | D14: 5162 | E14: =C14*D14 -> 25810 | F14: 4508.67 | G14: =C14*F14 -> 22543.35
A15: Герметик ТЕХНОНИКОЛЬ ПУ MASTER, серый, туба 600 мл | B15: шт | C15: ='СР (материалы ТН)'!C105+'СР (материалы ТН)'!C119 -> 11.25 | D15: 440 | E15: =C15*D15 -> 4950 | F15: 449.4 | G15: =C15*F15 -> 5055.75
A16: Саморез остроконечный ТехноНИКОЛЬ 4,8*50 (500 шт/уп) | B16: шт | C16: ='СР (материалы ТН)'!C116 -> 120 | D16: 7.5 | E16: =C16*D16 -> 900 | F16: 3.81 | G16: =C16*F16 -> 457.2
A17: Телескопический крепеж TERMOCLIP 1, 20 мм | B17: шт | C17: ='СР (материалы ТН)'!C83+'СР (материалы ТН)'!C73 -> 11232 | D17: 14 | E17: =C17*D17 -> 157248 | F17: 3.46 | G17: =C17*F17 -> 38862.72
A18: Доставка: | F18: 35000 | G18: 35000
A19: Всего: | E19: =SUM(E2:E18) -> 2673182.4 | G19: =SUM(G2:G18) -> 2511474
E24: 2673182.4
E26: =E19-E24 -> -0.0016000005
