Workbook

Sheet Блок 1
A1: Приложение №____ к Договору подряда № _____ от _________ г.
A3: Согласовано | D3: Утверждаю
A4: «Подрядчик» | D4: «Заказчик»
A5: ООО «СК-ЮГ» | D5: ООО «»
A6: ИНН / КПП 2312330110/ 231201001 | D6: ИНН / КПП
A7: Ген. Директор________________ (Панюков А.А.) | D7: Ген. Директор________________ ()
A10: СМЕТА №___
A11: по Договору подряда № __________ от ___________ г.
A14: Наименование объекта: «Склад хранения сельскохозяйственной продукции на земельном участке с кадастровым номером 23:43:0429001:1003»
A15: Адрес: г. Краснодар
A16: Данные крыши: Площадь кровли по профлисту = 6 477,4 м2; Примыкания к карнизному свесу = 364 пог.м; Примыкания к парапету по сендвич панели = 96 пог.м; Площадь кровли по ж/б = 337,3 м2; Примыкания к парапету по ж/б панели = 76,2 пог.м; Суммарная площадь контруклонов по ж/б основанию = 96 м2; Кол-во фахверков = 18 шт; Количество люков дымоудаления = 8 шт.; Монтаж не горючего материала = 212 м2; Система ОВ = 4 шт.; ВК = 1 шт. = 7,2 пог. м.; Водоотведение внутреннее по ж/б = 3 шт.; Водоотведение наружнее = 24 шт.; Кабельная система противообледенения L = 0 пог.м. Ограждение h=600 мм = 266 пог. м; Кол-во стоек ограждения = 266 шт.; Кол-во пешеходных дорожек = 265,45 пог. м.
A18: Наименование работ | B18: Ед.изм. | C18: Кол-во | D18: Цена за ед. без НДС | E18: Сумма без НДС
A19: УСТРОЙСТВО КРОВЕЛЬНОЙ СИСТЕМЫ ИЗ ПВХ-МЕМБРАНЫ
A20: Монтаж профилированного листа
A21: Работы:
A22: Монтаж профилированного листа Н75-750-0,8 | B22: м2 | C22: 6477.4 | D22: 230 | E22: =C22*D22 -> 1489802
A23: Итого за работы: | E23: =E22 -> 1489802
A24: Материалы:
A25: Профилированный лист Н75-750-0,8 | B25: м2 | C25: =C22*1.25 -> 8096.75 | E25: =C25*D25 -> 0
A26: Саморез для профлиста HARPOON HE5-R 5,5х32 углеродистая сталь SAE 1022 (1,2 шт/м2) | B26: шт | C26: =C22*1.5 -> 9716.1 | E26: =C26*D26 -> 0
A27: Заклепка вытяжная комбинированная 4,8х20 мм | B27: шт | C27: =C22*3 -> 19432.2 | E27: =C27*D27 -> 0
A28: Итого за материалы: | E28: =E25+E26+E27 -> 0
A29: ИТОГО по Разделу: | E29: =E23+E28 -> 1489802
A30: Заполнение гофр профлиста НГ утеплителем на ширину 250 мм и L-образного профиля в местах парапета, а также профилей усиления в ендове и на коньках
A31: Работы:
A32: Устройство заполнения гофр профлиста НГ утеплителем на длину 250 мм (на две продольной волны или 250 мм в каждую волну по поперечным волнам) | B32: м/п | C32: 364 | D32: 120 | E32: =C32*D32 -> 43680
A33: Устройство L-образного профиля и профилей усиления | B33: м/п | C33: =C32 -> 364 | D33: 160 | E33: =C33*D33 -> 58240
A34: Устройство профилей усиления (коньковые усиления, усиления ендов) | B34: м/п | C34: 133 | D34: 160 | E34: =C34*D34 -> 21280
A35: Устройство профилей усиления деф. шва | B35: м/п | C35: 0 | D35: 160 | E35: =C35*D35 -> 0
A36: Итого за работы: | E36: =SUM(E32:E35) -> 123200
A37: Материалы:
A38: Мин. плита Технолайт Экстра 1200х600х100мм | B38: м3 | C38: =C32*0.3*0.1*1.1 -> 12.012 | E38: =C38*D38 -> 0
A39: L-образный профиль | B39: =[1]Материал!B28 -> м3 | C39: =C33 -> 364 | D39: 1300 | E39: =C39*D39 -> 473200
A40: Профиль усиления (коньковые усиления, усиления ендов) | B40: =[1]Материал!B29 -> м3 | C40: =C34 -> 133 | D40: 1300 | E40: =C40*D40 -> 172900
A41: Профиль усиления деф. шва | B41: =[1]Материал!B30 -> м2 | C41: =C35 -> 0 | D41: 1300 | E41: =C41*D41 -> 0
A42: Саморез кровельный 4.8х29 сверлоконечный шайба EPDM | B42: шт | C42: =(C39+C40+C41)*2*5 -> 4970 | D42: 3.8 | E42: =C42*D42 -> 18886
A43: Итого за материалы: | E43: =SUM(E38:E42) -> 664986
A44: ИТОГО по Разделу: | E44: =E36+E43 -> 788186
A45: Устройство пароизоляционного слоя
A46: Работы:
...

Sheet Блок 2
A1: Приложение №____ к Договору подряда № _____ от _________ г.
A3: Согласовано | D3: Утверждаю
A4: «Подрядчик» | D4: «Заказчик»
A5: ООО «СК-ЮГ» | D5: ООО «»
A6: ИНН / КПП 2312330110/ 231201001 | D6: ИНН / КПП
A7: Ген. Директор________________ (Панюков А.А.) | D7: Ген. Директор________________ ()
A10: СМЕТА №___
A11: по Договору подряда № __________ от ___________ г.
A14: Наименование объекта: «Склад хранения сельскохозяйственной продукции на земельном участке с кадастровым номером 23:43:0429001:475»
A15: Адрес: г. Краснодар
A16: Данные крыши: Площадь кровли по профлисту = 10 310,5 м2; Примыкания к карнизному свесу = 426 пог.м; Примыкания к парапету по сендвич панели = 96 пог.м; Площадь кровли по ж/б = 337,3 м2; Примыкания к парапету по ж/б панели = 76,2 пог.м; Суммарная площадь контруклонов по ж/б основанию = 96 м2; Кол-во фахверков = 18 шт; Количество люков дымоудаления = 14 шт.; Монтаж не горючего материала = 371 м2; Система ОВ = 4 шт.; ВК = 1 шт. = 7,2 пог. м.; Водоотведение внутреннее по ж/б = 3 шт.; Водоотведение наружнее = 40 шт.; Кабельная система противообледенения L = 325 пог.м. Ограждение h=600 мм = 425 пог. м; Кол-во стоек ограждения = 425 шт.; Кол-во пешеходных дорожек = 436 пог. м.
A18: Наименование работ | B18: Ед.изм. | C18: Кол-во | D18: Цена за ед. без НДС | E18: Сумма без НДС
A19: УСТРОЙСТВО КРОВЕЛЬНОЙ СИСТЕМЫ ИЗ ПВХ-МЕМБРАНЫ
A20: Монтаж профилированного листа
A21: Работы:
A22: Монтаж профилированного листа Н75-750-0,8 | B22: м2 | C22: 10310.5 | D22: ='Блок 1'!D22 -> 230 | E22: =C22*D22 -> 2371415
A23: Итого за работы: | E23: =E22 -> 2371415
A24: Материалы:
A25: Профилированный лист Н75-750-0,8 | B25: м2 | C25: =C22*1.25 -> 12888.125 | D25: ='Блок 1'!D25 -> 0 | E25: =C25*D25 -> 0
A26: Саморез для профлиста HARPOON HE5-R 5,5х32 углеродистая сталь SAE 1022 (1,2 шт/м2) | B26: шт | C26: =C22*1.5 -> 15465.75 | D26: ='Блок 1'!D26 -> 0 | E26: =C26*D26 -> 0
A27: Заклепка вытяжная комбинированная 4,8х20 мм | B27: шт | C27: =C22*3 -> 30931.5 | D27: ='Блок 1'!D27 -> 0 | E27: =C27*D27 -> 0
A28: Итого за материалы: | E28: =E25+E26+E27 -> 0
A29: ИТОГО по Разделу: | E29: =E23+E28 -> 2371415
A30: Заполнение гофр профлиста НГ утеплителем на ширину 250 мм и L-образного профиля в местах парапета, а также профилей усиления в ендове и на коньках
A31: Работы:
A32: Устройство заполнения гофр профлиста НГ утеплителем на длину 250 мм (на две продольной волны или 250 мм в каждую волну по поперечным волнам) | B32: м/п | C32: 522 | D32: ='Блок 1'!D32 -> 120 | E32: =C32*D32 -> 62640
A33: Устройство L-образного профиля и профилей усиления | B33: м/п | C33: =C32 -> 522 | D33: ='Блок 1'!D33 -> 160 | E33: =C33*D33 -> 83520
A34: Устройство профилей усиления (коньковые усиления, усиления ендов) | B34: м/п | C34: 211.4 | D34: ='Блок 1'!D34 -> 160 | E34: =C34*D34 -> 33824
A35: Устройство профилей усиления деф. шва | B35: м/п | C35: 0 | D35: ='Блок 1'!D35 -> 160 | E35: =C35*D35 -> 0
A36: Итого за работы: | E36: =SUM(E32:E35) -> 179984
A37: Материалы:
A38: Мин. плита Технолайт Экстра 1200х600х100мм | B38: м3 | C38: =C32*0.3*0.1*1.1 -> 17.226 | D38: ='Блок 1'!D38 -> 0 | E38: =C38*D38 -> 0
A39: L-образный профиль | B39: =[1]Материал!B28 -> м3 | C39: =C33 -> 522 | D39: ='Блок 1'!D39 -> 1300 | E39: =C39*D39 -> 678600
A40: Профиль усиления (коньковые усиления, усиления ендов) | B40: =[1]Материал!B29 -> м3 | C40: =C34 -> 211.4 | D40: ='Блок 1'!D40 -> 1300 | E40: =C40*D40 -> 274820
A41: Профиль усиления деф. шва | B41: =[1]Материал!B30 -> м2 | C41: =C35 -> 0 | D41: ='Блок 1'!D41 -> 1300 | E41: =C41*D41 -> 0
A42: Саморез кровельный 4.8х29 сверлоконечный шайба EPDM | B42: шт | C42: =(C39+C40+C41)*2*5 -> 7334 | D42: ='Блок 1'!D42 -> 3.8 | E42: =C42*D42 -> 27869.2
A43: Итого за материалы: | E43: =SUM(E38:E42) -> 981289.2
A44: ИТОГО по Разделу: | E44: =E36+E43 -> 1161273.2
A45: Устройство пароизоляционного слоя
A46: Работы:
...
